<?xml version="1.0" ?>
<robot name="robot1" xmlns:xacro="https://www.ros.org/wiki/xacro" >

  <xacro:include filename="$(find final_assignment)/urdf/materials.xacro" />
  <xacro:include filename="$(find final_assignment)/urdf/robot.gazebo" />

  <xacro:macro name="side_wheel_inertia" >
        <inertial>
            <mass value="0.2" />
            <origin rpy="0 1.5707 1.5707" xyz="0 0 0"/>
            <inertia ixx="0.000526666666667" ixy="0" ixz="0" iyy="0.000526666666667" iyz="0" izz="0.001"/>
        </inertial>
	</xacro:macro>

  <xacro:macro name="side_wheel_geometry">
      <geometry>
        <cylinder length="0.04" radius="0.1"/>
      </geometry>
  </xacro:macro>

  <!-- MAIN BODY -->
  <link name="link_chassis">
    <pose>0 0 0.1 0 0 0</pose>
    <inertial>
      <mass value="5"/>
      <origin rpy="0 0 0" xyz="0 0 0.1"/>
      <inertia ixx="0.0395416666667" ixy="0" ixz="0" iyy="0.106208333333" iyz="0" izz="0.106208333333"/>
    </inertial>
    <!-- CHASSIS -->
    <collision name="collision_chassis">
      <geometry>
        <box size="0.5 0.3 0.07"/>
      </geometry>
    </collision>
    <visual>
      <origin rpy="0 0 0" xyz="0 0 0"/>
      <geometry>
        <box size="0.5 0.3 0.07"/>
      </geometry>
      <material name="orange"/>
    </visual>
    <!-- CASTER WHEEL FRONT -->
    <collision name="caster_front_collision">
      <origin rpy=" 0 0 0" xyz="0.35 0 -0.05"/>
      <geometry>
        <sphere radius="0.05"/>
      </geometry>
    </collision>
    <visual name="caster_front_visual">
      <origin rpy=" 0 0 0" xyz="0.2 0 -0.05"/>
      <geometry>
        <sphere radius="0.05"/>
      </geometry>
      <material name="white"/>
    </visual>
  </link>

  <!-- RIGHT WHEEL -->
  <link name="link_right_wheel">
    <xacro:side_wheel_inertia />
    <collision name="link_right_wheel_collision">
      <origin rpy="0 1.5707 1.5707" xyz="0 0 0"/>
      <xacro:side_wheel_geometry />
    </collision>
    <visual name="link_right_wheel_visual">
      <origin rpy="0 1.5707 1.5707" xyz="0 0 0"/>
      <xacro:side_wheel_geometry />
      <material name="red"/>
    </visual>
  </link>

  <joint name="joint_right_wheel" type="continuous">
    <origin rpy="0 0 0" xyz="-0.05 0.15 0"/>
    <child link="link_right_wheel"/>
    <parent link="link_chassis"/>
    <axis rpy="0 0 0" xyz="0 1 0"/>
    <limit effort="10000" velocity="1000"/>
    <joint_properties damping="1.0" friction="1.0"/>
  </joint>

  <!-- LEFT WHEEL -->
  <link name="link_left_wheel">
    <xacro:side_wheel_inertia />
    <collision name="link_left_wheel_collision">
      <origin rpy="0 1.5707 1.5707" xyz="0 0 0"/>
      <xacro:side_wheel_geometry />
    </collision>
    <visual name="link_left_wheel_visual">
      <origin rpy="0 1.5707 1.5707" xyz="0 0 0"/>
      <xacro:side_wheel_geometry />
      <material name="red"/>
    </visual>
  </link>

  <joint name="joint_left_wheel" type="continuous">
    <origin rpy="0 0 0" xyz="-0.05 -0.15 0"/>
    <child link="link_left_wheel"/>
    <parent link="link_chassis"/>
    <axis rpy="0 0 0" xyz="0 1 0"/>
    <limit effort="10000" velocity="1000"/>
    <joint_properties damping="1.0" friction="1.0"/>
  </joint>

  <!-- LASER -->
  <link name="hokuyo_link">
    <inertial>
      <mass value="1e-5"/>
      <origin rpy="0 0 0" xyz="0 0 0"/>
      <inertia ixx="1e-6" ixy="0" ixz="0" iyy="1e-6" iyz="0" izz="1e-6"/>
    </inertial>
    <collision>
      <origin rpy="0 0 0" xyz="0 0 0.025"/>
      <geometry>
        <box size="0.05 0.05 0.05"/>
      </geometry>
    </collision>
    <visual>
      <origin rpy="0 0 0" xyz="0 0 0.025"/>
      <geometry>
        <box size="0.05 0.05 0.05"/>
      </geometry>
      <material name="red">
        <color rgba="1 0 0 1"/>
      </material>
    </visual>
  </link>

  <joint name="hokuyo_joint" type="fixed">
    <axis xyz="0 1 0"/>
    <origin rpy="0 0 0" xyz="0.28 0 0.05"/>
    <parent link="link_chassis"/>
    <child link="hokuyo_link"/>
  </joint>

  <!-- ARM LINK 0 -->
  <link name="arm_link_0">
    <inertial>
      <mass value="0.01"/>
      <origin rpy="0 0 0" xyz="0 0 0"/>
      <inertia ixx="1.6e-5" ixy="0" ixz="0" iyy="1.6e-5" iyz="0" izz="1.6e-5"/>
    </inertial>
    <collision>
      <origin rpy="0 0 0" xyz="0 0 0"/>
      <geometry>
        <box size="0.08 0.08 0.08"/>
      </geometry>
    </collision>
    <visual>
      <origin rpy="0 0 0" xyz="0 0 0"/>
      <geometry>
        <box size="0.08 0.08 0.08"/>
      </geometry>
      <material name="green"/>
    </visual>
  </link>

  <joint name="arm_joint_0" type="revolute">
  	<axis xyz="0 0 1"/>
  	<limit effort="1.0" lower="-3.14" upper="3.14" velocity="0.01"/>
  	<origin rpy="0 0 0" xyz="0 0 0.086"/>
  	<parent link="link_chassis"/>
  	<child link="arm_link_0"/>
  </joint>

  <!-- ARM LINK 1-->
  <link name="arm_link_1">
    <inertial>
      <mass value="0.015"/>
      <origin rpy="0 0 0" xyz="0 0 0.15"/>
      <inertia ixx="1.1e-4" ixy="0" ixz="0" iyy="1.1e-4" iyz="0" izz="6.25e-6"/>
    </inertial>
    <collision>
      <origin rpy="0 0 0" xyz="0 0 0.15"/>
      <geometry>
        <box size="0.05 0.05 0.2"/>
      </geometry>
    </collision>
    <visual>
      <origin rpy="0 0 0" xyz="0 0 0.15"/>
      <geometry>
        <box size="0.05 0.05 0.2"/>
      </geometry>
      <material name="green"/>
    </visual>
  </link>

  <joint name="arm_joint_1" type="revolute">
  	<axis xyz="0 1 0"/>
  	<limit effort="1000.0" lower="-1.2" upper="1.2" velocity="0.01"/>
  	<origin rpy="0 0 0" xyz="0 0 0.051"/>
  	<parent link="arm_link_0"/>
  	<child link="arm_link_1"/>
  </joint>

  <!-- CAMERA LINK -->
  <link name="camera_link">
    <inertial>
      <mass value="0.01"/>
      <origin rpy="0 0 0" xyz="0 0 0"/>
      <inertia ixx="4.1e-6" ixy="0" ixz="0" iyy="4.1e-6" iyz="0" izz="4.1e-6"/>
    </inertial>
    <collision>
      <origin rpy="0 0 0" xyz="0 0 0"/>
      <geometry>
        <box size="0.05 0.05 0.05"/>
      </geometry>
    </collision>
    <visual>
      <origin rpy="0 0 0" xyz="0 0 0"/>
      <geometry>
        <box size="0.05 0.05 0.05"/>
      </geometry>
      <material name="brown"/>
    </visual>
  </link>

  <joint name="camera_joint" type="revolute">
  	<axis xyz="0 1 0"/>
  	<limit effort="1000.0" lower="-1.2" upper="1.2" velocity="0.01"/>
  	<origin rpy="0 0 0" xyz="0.025 0 0.326"/>
  	<parent link="arm_link_1"/>
  	<child link="camera_link"/>
  </joint>

  <!-- DEFINING THE TRANSMISSIONS -->

  <transmission name="arm_joint_0_trans">
    <type>transmission_interface/SimpleTransmission</type>
    <joint name="arm_joint_0">
      <hardwareInterface>hardware_interface/EffortJointInterface</hardwareInterface>
    </joint>
    <actuator name="motor0">
      <hardwareInterface>hardware_interface/EffortJointInterface</hardwareInterface>
      <mechanicalInterface>1</mechanicalInterface>
    </actuator>
  </transmission>

  <transmission name="arm_joint_1_trans">
    <type>transmission_interface/SimpleTransmission</type>
    <joint name="arm_joint_1">
      <hardwareInterface>hardware_interface/EffortJointInterface</hardwareInterface>
    </joint>
    <actuator name="motor1">
      <hardwareInterface>hardware_interface/EffortJointInterface</hardwareInterface>
      <mechanicalInterface>1</mechanicalInterface>
    </actuator>
  </transmission>

  <transmission name="camera_joint_trans">
    <type>transmission_interface/SimpleTransmission</type>
    <joint name="camera_joint">
      <hardwareInterface>hardware_interface/EffortJointInterface</hardwareInterface>
    </joint>
    <actuator name="motor2">
      <hardwareInterface>hardware_interface/EffortJointInterface</hardwareInterface>
      <mechanicalInterface>1</mechanicalInterface>
    </actuator>
  </transmission>

</robot>
