<?xml version="1.0" ?>
<robot name="robot_assignment" xmlns:xacro="https://www.ros.org/wiki/xacro">

  <xacro:include filename="$(find final_assignment)/urdf/materials.xacro" />
  <xacro:include filename="$(find final_assignment)/urdf/robot_assignment.gazebo" />

  <xacro:macro name="cylinder_inertia" params="mass r l"> 
    <inertia 
      ixx="${mass*(3*r*r+l*l)/12}" ixy = "0" ixz = "0"
      iyy="${mass*(3*r*r+l*l)/12}" iyz = "0" izz="${mass*(r*r)/2}" 
    /> 
  </xacro:macro>

  <xacro:macro name="link_wheel" params="name">
    <link name="${name}">
      <inertial>
        <mass value="0.2"/>
        <origin rpy="0 1.5707 1.5707" xyz="0 0 0"/>
      <inertia ixx="0.000526666666667" ixy="0" ixz="0" iyy="0.000526666666667" iyz="0" izz="0.001"/>
      </inertial>
      <collision name="link_right_wheel_collision">
        <origin rpy="0 1.5707 1.5707" xyz="0 0 0"/>
        <geometry>
          <cylinder length="0.04" radius="0.1"/>
        </geometry>
      </collision>
      <visual name="${name}_visual">
        <origin rpy="0 1.5707 1.5707" xyz="0 0 0"/>
        <geometry>
          <cylinder length="0.04" radius="0.1"/>
        </geometry>
      </visual>
    </link>
  </xacro:macro>

  <xacro:macro name="link_arm" params="name length xyz_origin">
		<link name="${name}">
			<inertial>
				<origin xyz="0 0 0" rpy="0 0 0"/>
				<mass value="0.025"/>
				<inertia ixx="0.000010279" ixy="0" ixz="0" iyy="0.000010279" iyz="0" izz="0.000007225"/>
			</inertial>
			<collision name="${name}_collision">
				<origin rpy="0 0 0" xyz="${xyz_origin}"/>
        <geometry>
          <cylinder length="${length}" radius="0.04"/>
        </geometry>
			</collision>
			<visual name="${name}_visual">
				<origin rpy="0 0 0" xyz="${xyz_origin}"/>
        <geometry>
          <cylinder length="${length}" radius="0.04"/>
        </geometry>
			</visual>
		</link>
	</xacro:macro>
 
  <xacro:macro name="joint_wheel" params="name child origin_xyz">
    <joint name="${name}" type="continuous">
      <origin rpy="0 0 0" xyz="${origin_xyz}"/>
      <child link="${child}"/>
      <parent link="base_link"/>
      <axis rpy="0 0 0" xyz="0 1 0"/>
      <limit effort="10000" velocity="1000"/>
      <joint_properties damping="1.0" friction="1.0"/>
    </joint>
  </xacro:macro>

  <xacro:macro name="joint_arm" params="name parent child origin_xyz axis_xyz">
    <joint name="${name}" type="revolute">
      <axis xyz="${axis_xyz}"/>
      <limit effort="1000.0" lower="-3.14" upper="3.14" velocity="0.02"/>
      <origin rpy="0 0 0" xyz="${origin_xyz}"/>
      <parent link="${parent}"/>
      <child link="${child}"/>
      <joint_properties damping="1.0" friction="1.0"/>
    </joint>
  </xacro:macro>


  <!-- MAIN BODY -->
  <link name="base_link">
    <pose>0 0 0.1 0 0 0</pose>
    <inertial>
      <mass value="5"/>
      <origin rpy="0 0 0" xyz="0 0 0.1"/>
      <inertia ixx="0.0395416666667" ixy="0" ixz="0" iyy="0.106208333333" iyz="0" izz="0.106208333333"/>
    </inertial>
    <!-- CHASSIS -->
    <collision name="collision_chassis">
      <geometry>
      <box size="0.5 0.3 0.07"/>
      </geometry>
    </collision>
    <visual>
      <origin rpy="0 0 0" xyz="0 0 0"/>
      <geometry>
        <box size="0.5 0.3 0.07"/>
      </geometry>
      <material name="blue"/>
    </visual>
    <!-- CASTER FRONT -->
    <collision name="caster_front_collision">
      <origin rpy=" 0 0 0" xyz="0.35 0 -0.05"/>
      <geometry>
        <sphere radius="0.05"/>
      </geometry>
      <surface>
        <friction>
          <ode>
            <mu>0</mu>
            <mu2>0</mu2>
            <slip1>1.0</slip1>
            <slip2>1.0</slip2>
          </ode>
        </friction>
      </surface>
    </collision>
    <visual name="caster_front_visual">
      <origin rpy=" 0 0 0" xyz="0.2 0 -0.05"/>
      <geometry>
        <sphere radius="0.05"/>
      </geometry>
    </visual>
  </link>


  <!-- WHEEL RIGHT -->
  <xacro:link_wheel name="link_right_wheel" />
  <xacro:joint_wheel name="joint_right_wheel"  child="link_right_wheel"  origin_xyz="-0.05 0.15 0"  />


  <!-- WHEEL LEFT -->
  <xacro:link_wheel name="link_left_wheel" />
  <xacro:joint_wheel name="joint_left_wheel"   child="link_left_wheel"   origin_xyz="-0.05 -0.15 0"  />


  <!-- LASER -->
  <link name="laser">
    <inertial>
      <origin xyz="0 0 0" rpy="0 0 0" />
      <mass value="1" />
      <xacro:cylinder_inertia mass="1" r="0.05" l="0.1" />
    </inertial>
    <visual>
      <origin xyz="0 0 0" rpy="0 0 0" />
      <geometry>
        <cylinder radius="0.05" length="0.1"/>
      </geometry>
      <material name="white" />
    </visual>
    <collision>
      <origin xyz="0 0 0" rpy="0 0 0"/>
      <geometry>
        <cylinder radius="0.05" length="0.1"/>
      </geometry>
    </collision>
  </link>

  <joint name="joint_laser" type="fixed">
    <origin xyz="0.30 0 0.05" rpy="0 0 0"/>
    <parent link="base_link"/>
    <child link="laser"/>
  </joint>


  <!-- ARM BASE LINK -->
  <link name="arm_base_link">
  	<inertial>
  		<mass value="0.1"/>
  		<origin xyz="0 0 0" rpy="0 0 0" />
  		<inertia ixx="0.0000416666667" ixy="0" ixz="0" iyy="0.0000416666667" iyz="0" izz="0.0000416666667"/>
  	</inertial>
  	<collision>
  	  <origin xyz="0 0 0" rpy="0 0 0"/>
      <geometry>
        <box size="0.1 0.1 0.1"/>
      </geometry>
  	</collision>
  	<visual>
  	  <origin xyz="0 0 0" rpy="0 0 0"/>
      <geometry>
        <box size="0.1 0.1 0.1"/>
      </geometry>
      <material name="red" />
  	</visual>
  </link>

  <joint name="arm_base_to_base" type="fixed">
  	<origin rpy="0 0 0" xyz="0 0 0.05"/>
  	<parent link="base_link"/>
  	<child link="arm_base_link"/>
  </joint>

  <!-- ARM 0 -->
  <xacro:link_arm name="arm_link_01" length="0.15" xyz_origin="0 0 0.075"/>
  <xacro:joint_arm name="arm_joint_01" child="arm_link_01" parent="arm_base_link" origin_xyz="0 0 0.025" axis_xyz="0 0 1"/>

  <!-- ARM 1 -->
  <xacro:link_arm name="arm_link_02" length="0.15" xyz_origin="0 0 0.075"/>
  <xacro:joint_arm name="arm_joint_02" child="arm_link_02" parent="arm_link_01" origin_xyz="0 0 0.15" axis_xyz="1 0 0"/>

  <!-- ARM 2 -->
  <xacro:link_arm name="arm_link_03" length="0.06" xyz_origin="0 0 0.03"/>
  <xacro:joint_arm name="arm_joint_03" child="arm_link_03" parent="arm_link_02" origin_xyz="0 0 0.15" axis_xyz="0 1 0"/>


  <!-- CAMERA -->
  <link name="camera_link">
  	<inertial>
  		<mass value="0.025"/>
  		<origin xyz="0 0 0" rpy="0 0 0" />
  		<inertia ixx="0.000010279" ixy="0" ixz="0" iyy="0.000010279" iyz="0" izz="0.000007225"/>
  	</inertial>
  	<collision>
  	  <origin xyz="0 0 0" rpy="0 0 0"/>
      <geometry>
        <box size="0.08 0.08 0.08"/>
      </geometry>
  	</collision>
  	<visual>
  	  <origin xyz="0 0 0" rpy="0 0 1.57"/>
      <geometry>
        <box size="0.08 0.08 0.08"/>
      </geometry>
      <material name="red" >
        <color rgba="1 0 0 1"/>
      </material>
  	</visual>
  </link>

  <joint name="camera_joint" type="fixed">
  	<origin rpy="0 0 0" xyz="0 0 0.1"/>
  	<parent link="arm_link_03"/>
  	<child link="camera_link"/>
  </joint>


  <!-- TRANSMISSION -->
  <transmission name="arm_joint_01_trans">
    <type>transmission_interface/SimpleTransmission</type>
    <joint name="arm_joint_01">
      <hardwareInterface>hardware_interface/EffortJointInterface</hardwareInterface>
    </joint>
    <actuator name="motor1">
      <hardwareInterface>hardware_interface/EffortJointInterface</hardwareInterface>
      <mechanicalInterface>1</mechanicalInterface>
    </actuator>
  </transmission>

  <transmission name="arm_joint_02_trans">
    <type>transmission_interface/SimpleTransmission</type>
    <joint name="arm_joint_02">
      <hardwareInterface>hardware_interface/EffortJointInterface</hardwareInterface>
    </joint>
    <actuator name="motor2">
      <hardwareInterface>hardware_interface/EffortJointInterface</hardwareInterface>
      <mechanicalInterface>1</mechanicalInterface>
    </actuator>
  </transmission>

  <transmission name="arm_joint_03_trans">
    <type>transmission_interface/SimpleTransmission</type>
    <joint name="arm_joint_03">
      <hardwareInterface>hardware_interface/EffortJointInterface</hardwareInterface>
    </joint>
    <actuator name="motor3">
      <hardwareInterface>hardware_interface/EffortJointInterface</hardwareInterface>
      <mechanicalInterface>1</mechanicalInterface>
    </actuator>
  </transmission>

</robot>
